[2019-01-24 11:56:41.338628] [mpm_winnt:notice] [pid 12136:tid 704] mpm_winnt.c(1730): AH00455: Apache/2.4.33 (Win64) OpenSSL/1.0.2m mod_wsgi/4.5.15 Python/2.7 configured -- resuming normal operations
[2019-01-24 11:56:41.338628] [mpm_winnt:notice] [pid 12136:tid 704] mpm_winnt.c(1733): AH00456: Server built: May 17 2018 13:03:53
[2019-01-24 11:56:41.338628] [core:notice] [pid 12136:tid 704] log.c(1560): AH00094: Command line: 'C:\\cdb\\CONTACT_Elements_Server_15.3.13\\httpd.exe -d C:/cdb/CONTACT_Elements_Server_15.3.13 -d C:/cdb/CONTACT_Elements_Server_15.3.13 -f C:/cdb/rbei/tmp/httphrdx7i.conf -D WIN32 -D USE_SSL -D USE_CACHE'
[2019-01-24 11:56:41.354255] [mpm_winnt:notice] [pid 12136:tid 704] mpm_winnt.c(649): AH00418: Parent: Created child process 13024
Apache server interrupted...
[mpm_winnt:notice] [pid 13024:tid 932] child.c(968): AH00354: Child: Starting 256 worker threads.
[2019-01-24 11:57:05.622459] [cache:error] [pid 13024:tid 3016] [client fe80::91bf:dbee:3230:e1f1:55175] [u9+aTMZ1oQQ] [(OS 5)Access is denied.  ] cache_util.c(355): AH00779: Could not stat a cache lock file: C:/cdb/rbei/etcd/mod_cache-lock/s/j/sjyc@B3yr4kSljHqiiW0Dg
[2019-01-24 11:57:10.638618] [cache:error] [pid 13024:tid 3012] [client fe80::91bf:dbee:3230:e1f1:55176] [Di3nTFZWoAQ] [(OS 5)Access is denied.  ] cache_util.c(355): AH00779: Could not stat a cache lock file: C:/cdb/rbei/etcd/mod_cache-lock/s/j/sjyc@B3yr4kSljHqiiW0Dg
[2019-01-24 16:42:59.720280] [mpm_winnt:notice] [pid 12136:tid 704] mpm_winnt.c(811): AH00422: Parent: Received shutdown signal -- Shutting down the server.
Apache server interrupted...
[2019-01-24 16:46:38.734011] [mpm_winnt:notice] [pid 14652:tid 944] mpm_winnt.c(1730): AH00455: Apache/2.4.33 (Win64) OpenSSL/1.0.2m mod_wsgi/4.5.15 Python/2.7 configured -- resuming normal operations
[2019-01-24 16:46:38.744040] [mpm_winnt:notice] [pid 14652:tid 944] mpm_winnt.c(1733): AH00456: Server built: May 17 2018 13:03:53
[2019-01-24 16:46:38.744040] [core:notice] [pid 14652:tid 944] log.c(1560): AH00094: Command line: 'C:\\cdb\\CONTACT_Elements_Server_15.3.13\\httpd.exe -d C:/cdb/CONTACT_Elements_Server_15.3.13 -d C:/cdb/CONTACT_Elements_Server_15.3.13 -f C:/cdb/rbei/tmp/httpjuh2vw.conf -D WIN32 -D USE_SSL -D USE_CACHE'
[2019-01-24 16:46:38.768103] [mpm_winnt:notice] [pid 14652:tid 944] mpm_winnt.c(649): AH00418: Parent: Created child process 14632
[2019-01-24 16:46:46.924794] [mpm_winnt:notice] [pid 14632:tid 616] child.c(968): AH00354: Child: Starting 256 worker threads.
[2019-01-24 16:46:52.003564] [cache:error] [pid 14632:tid 3024] [client fe80::91bf:dbee:3230:e1f1:61961] [mLDpWBo+IwU] [(OS 5)Access is denied.  ] cache_util.c(355): AH00779: Could not stat a cache lock file: C:/cdb/rbei/etcd/mod_cache-lock/s/j/sjyc@B3yr4kSljHqiiW0Dg
[2019-01-24 16:47:12.452919] [cache:error] [pid 14632:tid 3016] [client fe80::91bf:dbee:3230:e1f1:61982] [i/chWnp9IQU] [(OS 5)Access is denied.  ] cache_util.c(355): AH00779: Could not stat a cache lock file: C:/cdb/rbei/etcd/mod_cache-lock/s/j/sjyc@B3yr4kSljHqiiW0Dg
[2019-01-24 16:47:12.453923] [cache:error] [pid 14632:tid 3016] [client fe80::91bf:dbee:3230:e1f1:61982] [i/chWnp9IQU] [(OS 5)Access is denied.  ] cache_util.c(355): AH00779: Could not stat a cache lock file: C:/cdb/rbei/etcd/mod_cache-lock/s/j/sjyc@B3yr4kSljHqiiW0Dg
[2019-01-24 16:47:17.479286] [cache:error] [pid 14632:tid 3012] [client fe80::91bf:dbee:3230:e1f1:61983] [ta1uWlrLxAU] [(OS 5)Access is denied.  ] cache_util.c(355): AH00779: Could not stat a cache lock file: C:/cdb/rbei/etcd/mod_cache-lock/s/j/sjyc@B3yr4kSljHqiiW0Dg
[2019-01-24 16:47:17.480289] [cache:error] [pid 14632:tid 3012] [client fe80::91bf:dbee:3230:e1f1:61983] [ta1uWlrLxAU] [(OS 5)Access is denied.  ] cache_util.c(355): AH00779: Could not stat a cache lock file: C:/cdb/rbei/etcd/mod_cache-lock/s/j/sjyc@B3yr4kSljHqiiW0Dg
[2019-01-24 16:47:22.672093] [mpm_winnt:notice] [pid 14652:tid 944] mpm_winnt.c(811): AH00422: Parent: Received shutdown signal -- Shutting down the server.
[2019-01-24 16:51:47.417584] [mpm_winnt:notice] [pid 15244:tid 808] mpm_winnt.c(1730): AH00455: Apache/2.4.33 (Win64) OpenSSL/1.0.2m mod_wsgi/4.5.15 Python/2.7 configured -- resuming normal operations
[2019-01-24 16:51:47.426109] [mpm_winnt:notice] [pid 15244:tid 808] mpm_winnt.c(1733): AH00456: Server built: May 17 2018 13:03:53
[2019-01-24 16:51:47.426109] [core:notice] [pid 15244:tid 808] log.c(1560): AH00094: Command line: 'C:\\cdb\\CONTACT_Elements_Server_15.3.13\\httpd.exe -d C:/cdb/CONTACT_Elements_Server_15.3.13 -d C:/cdb/CONTACT_Elements_Server_15.3.13 -f C:/cdb/rbei/tmp/httpbsmywk.conf -D WIN32 -D USE_SSL -D USE_CACHE'
[2019-01-24 16:51:47.476743] [mpm_winnt:notice] [pid 15244:tid 808] mpm_winnt.c(649): AH00418: Parent: Created child process 5424
Apache server shutdown initiated...
nnt:notice] [pid 5424:tid 1104] child.c(968): AH00354: Child: Starting 256 worker threads.
[2019-01-24 16:52:11.427932] [cache:error] [pid 5424:tid 3024] [client fe80::91bf:dbee:3230:e1f1:62052] [B4nza9qliQQ] [(OS 5)Access is denied.  ] cache_util.c(355): AH00779: Could not stat a cache lock file: C:/cdb/rbei/etcd/mod_cache-lock/s/j/sjyc@B3yr4kSljHqiiW0Dg
[2019-01-24 16:52:19.588132] [cache:error] [pid 5424:tid 3016] [client fe80::91bf:dbee:3230:e1f1:62066] [kHZwbMqFiQQ] [(OS 5)Access is denied.  ] cache_util.c(355): AH00779: Could not stat a cache lock file: C:/cdb/rbei/etcd/mod_cache-lock/s/j/sjyc@B3yr4kSljHqiiW0Dg
[2019-01-24 16:52:19.591141] [cache:error] [pid 5424:tid 3016] [client fe80::91bf:dbee:3230:e1f1:62066] [kHZwbMqFiQQ] [(OS 5)Access is denied.  ] cache_util.c(355): AH00779: Could not stat a cache lock file: C:/cdb/rbei/etcd/mod_cache-lock/s/j/sjyc@B3yr4kSljHqiiW0Dg
[2019-01-24 16:52:24.619512] [cache:error] [pid 5424:tid 3012] [client fe80::91bf:dbee:3230:e1f1:62073] [bTq9bKqMZwU] [(OS 5)Access is denied.  ] cache_util.c(355): AH00779: Could not stat a cache lock file: C:/cdb/rbei/etcd/mod_cache-lock/s/j/sjyc@B3yr4kSljHqiiW0Dg
[2019-01-24 16:52:24.620515] [cache:error] [pid 5424:tid 3012] [client fe80::91bf:dbee:3230:e1f1:62073] [bTq9bKqMZwU] [(OS 5)Access is denied.  ] cache_util.c(355): AH00779: Could not stat a cache lock file: C:/cdb/rbei/etcd/mod_cache-lock/s/j/sjyc@B3yr4kSljHqiiW0Dg
[2019-01-24 16:52:29.658918] [cache:error] [pid 5424:tid 3008] [client fe80::91bf:dbee:3230:e1f1:62075] [iyEKbbqsZwU] [(OS 5)Access is denied.  ] cache_util.c(355): AH00779: Could not stat a cache lock file: C:/cdb/rbei/etcd/mod_cache-lock/s/j/sjyc@B3yr4kSljHqiiW0Dg
[2019-01-24 16:52:29.663926] [cache:error] [pid 5424:tid 3008] [client fe80::91bf:dbee:3230:e1f1:62075] [iyEKbbqsZwU] [(OS 5)Access is denied.  ] cache_util.c(355): AH00779: Could not stat a cache lock file: C:/cdb/rbei/etcd/mod_cache-lock/s/j/sjyc@B3yr4kSljHqiiW0Dg
[2019-01-24 16:52:34.673747] [cache:error] [pid 5424:tid 3004] [client fe80::91bf:dbee:3230:e1f1:62081] [n6xWbXosZgU] [(OS 5)Access is denied.  ] cache_util.c(355): AH00779: Could not stat a cache lock file: C:/cdb/rbei/etcd/mod_cache-lock/s/j/sjyc@B3yr4kSljHqiiW0Dg
[2019-01-24 16:52:34.675252] [cache:error] [pid 5424:tid 3004] [client fe80::91bf:dbee:3230:e1f1:62081] [n6xWbXosZgU] [(OS 5)Access is denied.  ] cache_util.c(355): AH00779: Could not stat a cache lock file: C:/cdb/rbei/etcd/mod_cache-lock/s/j/sjyc@B3yr4kSljHqiiW0Dg
[2019-01-24 16:52:57.593164] [mpm_winnt:notice] [pid 15244:tid 808] mpm_winnt.c(811): AH00422: Parent: Received shutdown signal -- Shutting down the server.
[2019-01-24 16:52:59.596671] [mpm_winnt:notice] [pid 5424:tid 1104] child.c(1252): AH00364: Child: All worker threads have exited.
[2019-01-24 16:52:59.668628] [mpm_winnt:notice] [pid 15244:tid 808] mpm_winnt.c(901): AH00430: Parent: Child process 5424 exited successfully.
[2019-01-24 16:54:25.264307] [mpm_winnt:notice] [pid 14236:tid 568] mpm_winnt.c(1730): AH00455: Apache/2.4.33 (Win64) OpenSSL/1.0.2m mod_wsgi/4.5.15 Python/2.7 configured -- resuming normal operations
[2019-01-24 16:54:25.283861] [mpm_winnt:notice] [pid 14236:tid 568] mpm_winnt.c(1733): AH00456: Server built: May 17 2018 13:03:53
[2019-01-24 16:54:25.283861] [core:notice] [pid 14236:tid 568] log.c(1560): AH00094: Command line: 'C:\\cdb\\CONTACT_Elements_Server_15.3.13\\httpd.exe -d C:/cdb/CONTACT_Elements_Server_15.3.13 -d C:/cdb/CONTACT_Elements_Server_15.3.13 -f C:/cdb/rbei/tmp/httpl3w6q4.conf -D WIN32 -D USE_SSL -D USE_CACHE'
[2019-01-24 16:54:25.340510] [mpm_winnt:notice] [pid 14236:tid 568] mpm_winnt.c(649): AH00418: Parent: Created child process 11800
Apache server shutdown initiated...
nnt:notice] [pid 11800:tid 892] child.c(968): AH00354: Child: Starting 256 worker threads.
[2019-01-25 09:43:05.506558] [wsgi:error] [pid 11800:tid 3008] [client fe80::91bf:dbee:3230:e1f1:63998] [PvELi0gOHwU] wsgi_logger.c(628): mod_wsgi (pid=11800): Exception occurred processing WSGI script 'C:/cdb/CONTACT_Elements_Server_15.3.13/cdb/python/cdb/wsgi/dispatcher/app.py'.
[2019-01-25 09:43:05.506558] [wsgi:error] [pid 11800:tid 3008] [client fe80::91bf:dbee:3230:e1f1:63998] [PvELi0gOHwU] wsgi_logger.c(147): Traceback (most recent call last):
[2019-01-25 09:43:05.506558] [wsgi:error] [pid 11800:tid 3008] [client fe80::91bf:dbee:3230:e1f1:63998] [PvELi0gOHwU] wsgi_logger.c(147):   File "C:\\cdb\\CONTACT_Elements_Server_15.3.13\\cdb\\python\\cdb\\wsgi\\middleware.py", line 708, in __call__
[2019-01-25 09:43:05.540649] [wsgi:error] [pid 11800:tid 3008] [client fe80::91bf:dbee:3230:e1f1:63998] [PvELi0gOHwU] wsgi_logger.c(147):     return self.app(environ, start_response)
[2019-01-25 09:43:05.540649] [wsgi:error] [pid 11800:tid 3008] [client fe80::91bf:dbee:3230:e1f1:63998] [PvELi0gOHwU] wsgi_logger.c(147):   File "C:\\cdb\\CONTACT_Elements_Server_15.3.13\\cdb\\python\\cdb\\wsgi\\middleware.py", line 736, in __call__
[2019-01-25 09:43:05.540649] [wsgi:error] [pid 11800:tid 3008] [client fe80::91bf:dbee:3230:e1f1:63998] [PvELi0gOHwU] wsgi_logger.c(147):     return self.app(environ, check_status)
[2019-01-25 09:43:05.540649] [wsgi:error] [pid 11800:tid 3008] [client fe80::91bf:dbee:3230:e1f1:63998] [PvELi0gOHwU] wsgi_logger.c(147):   File "C:\\cdb\\CONTACT_Elements_Server_15.3.13\\cdb\\python\\cdb\\wsgi\\middleware.py", line 759, in __call__
[2019-01-25 09:43:05.540649] [wsgi:error] [pid 11800:tid 3008] [client fe80::91bf:dbee:3230:e1f1:63998] [PvELi0gOHwU] wsgi_logger.c(147):     return self.app(environ, _remove_content_length)
[2019-01-25 09:43:05.540649] [wsgi:error] [pid 11800:tid 3008] [client fe80::91bf:dbee:3230:e1f1:63998] [PvELi0gOHwU] wsgi_logger.c(147):   File "C:\\cdb\\CONTACT_Elements_Server_15.3.13\\cdb\\python\\cdb\\wsgi\\dispatcher\\helpers.py", line 132, in __call__
[2019-01-25 09:43:05.611837] [wsgi:error] [pid 11800:tid 3008] [client fe80::91bf:dbee:3230:e1f1:63998] [PvELi0gOHwU] wsgi_logger.c(147):     return app(environ, start_response)
[2019-01-25 09:43:05.611837] [wsgi:error] [pid 11800:tid 3008] [client fe80::91bf:dbee:3230:e1f1:63998] [PvELi0gOHwU] wsgi_logger.c(147):   File "C:\\cdb\\CONTACT_Elements_Server_15.3.13\\cdb\\python\\cdb\\wsgi\\middleware.py", line 126, in __call__
[2019-01-25 09:43:05.611837] [wsgi:error] [pid 11800:tid 3008] [client fe80::91bf:dbee:3230:e1f1:63998] [PvELi0gOHwU] wsgi_logger.c(147):     environ, start_response)
[2019-01-25 09:43:05.611837] [wsgi:error] [pid 11800:tid 3008] [client fe80::91bf:dbee:3230:e1f1:63998] [PvELi0gOHwU] wsgi_logger.c(147):   File "C:\\cdb\\CONTACT_Elements_Server_15.3.13\\lib\\site-packages\\beaker-1.9.0-py2.7.egg\\beaker\\middleware.py", line 156, in __call__
[2019-01-25 09:43:05.647934] [wsgi:error] [pid 11800:tid 3008] [client fe80::91bf:dbee:3230:e1f1:63998] [PvELi0gOHwU] wsgi_logger.c(147):     return self.wrap_app(environ, session_start_response)
[2019-01-25 09:43:05.647934] [wsgi:error] [pid 11800:tid 3008] [client fe80::91bf:dbee:3230:e1f1:63998] [PvELi0gOHwU] wsgi_logger.c(147):   File "C:\\cdb\\CONTACT_Elements_Server_15.3.13\\cdb\\python\\cdb\\wsgi\\dispatcher\\helpers.py", line 594, in __call__
[2019-01-25 09:43:05.647934] [wsgi:error] [pid 11800:tid 3008] [client fe80::91bf:dbee:3230:e1f1:63998] [PvELi0gOHwU] wsgi_logger.c(147):     return self.app(environ, start_response)
[2019-01-25 09:43:05.647934] [wsgi:error] [pid 11800:tid 3008] [client fe80::91bf:dbee:3230:e1f1:63998] [PvELi0gOHwU] wsgi_logger.c(147):   File "C:\\cdb\\CONTACT_Elements_Server_15.3.13\\cdb\\python\\cdb\\wsgi\\middleware.py", line 292, in __call__
[2019-01-25 09:43:05.647934] [wsgi:error] [pid 11800:tid 3008] [client fe80::91bf:dbee:3230:e1f1:63998] [PvELi0gOHwU] wsgi_logger.c(147):     return self.app(environ, start_response)
[2019-01-25 09:43:05.647934] [wsgi:error] [pid 11800:tid 3008] [client fe80::91bf:dbee:3230:e1f1:63998] [PvELi0gOHwU] wsgi_logger.c(147):   File "C:\\cdb\\CONTACT_Elements_Server_15.3.13\\cdb\\python\\cdb\\wsgi\\middleware.py", line 244, in __call__
[2019-01-25 09:43:05.648937] [wsgi:error] [pid 11800:tid 3008] [client fe80::91bf:dbee:3230:e1f1:63998] [PvELi0gOHwU] wsgi_logger.c(147):     return self.app(environ, add_headers)
[2019-01-25 09:43:05.648937] [wsgi:error] [pid 11800:tid 3008] [client fe80::91bf:dbee:3230:e1f1:63998] [PvELi0gOHwU] wsgi_logger.c(147):   File "C:\\cdb\\CONTACT_Elements_Server_15.3.13\\cdb\\python\\cdb\\wsgi\\middleware.py", line 268, in __call__
[2019-01-25 09:43:05.648937] [wsgi:error] [pid 11800:tid 3008] [client fe80::91bf:dbee:3230:e1f1:63998] [PvELi0gOHwU] wsgi_logger.c(147):     return self.app(environ, add_header)
[2019-01-25 09:43:05.648937] [wsgi:error] [pid 11800:tid 3008] [client fe80::91bf:dbee:3230:e1f1:63998] [PvELi0gOHwU] wsgi_logger.c(147):   File "C:\\cdb\\CONTACT_Elements_Server_15.3.13\\cdb\\python\\cdb\\wsgi\\dispatcher\\helpers.py", line 355, in __call__
[2019-01-25 09:43:05.648937] [wsgi:error] [pid 11800:tid 3008] [client fe80::91bf:dbee:3230:e1f1:63998] [PvELi0gOHwU] wsgi_logger.c(147):     app, app_name, path_components)
[2019-01-25 09:43:05.648937] [wsgi:error] [pid 11800:tid 3008] [client fe80::91bf:dbee:3230:e1f1:63998] [PvELi0gOHwU] wsgi_logger.c(147):   File "C:\\cdb\\CONTACT_Elements_Server_15.3.13\\cdb\\python\\cdb\\wsgi\\dispatcher\\helpers.py", line 198, in _handle_logged_in
[2019-01-25 09:43:05.648937] [wsgi:error] [pid 11800:tid 3008] [client fe80::91bf:dbee:3230:e1f1:63998] [PvELi0gOHwU] wsgi_logger.c(147):     return app(environ, start_response)
[2019-01-25 09:43:05.648937] [wsgi:error] [pid 11800:tid 3008] [client fe80::91bf:dbee:3230:e1f1:63998] [PvELi0gOHwU] wsgi_logger.c(147):   File "C:\\cdb\\CONTACT_Elements_Server_15.3.13\\cdb\\python\\cdb\\wsgi\\auth\\sso.py", line 124, in __call__
[2019-01-25 09:43:05.725139] [wsgi:error] [pid 11800:tid 3008] [client fe80::91bf:dbee:3230:e1f1:63998] [PvELi0gOHwU] wsgi_logger.c(147):     return self.app(env, start_response)
[2019-01-25 09:43:05.725139] [wsgi:error] [pid 11800:tid 3008] [client fe80::91bf:dbee:3230:e1f1:63998] [PvELi0gOHwU] wsgi_logger.c(147):   File "C:\\cdb\\CONTACT_Elements_Server_15.3.13\\cdb\\python\\cdb\\wsgi\\middleware.py", line 775, in __call__
[2019-01-25 09:43:05.725139] [wsgi:error] [pid 11800:tid 3008] [client fe80::91bf:dbee:3230:e1f1:63998] [PvELi0gOHwU] wsgi_logger.c(147):     return self.app(env, start_response)
[2019-01-25 09:43:05.725139] [wsgi:error] [pid 11800:tid 3008] [client fe80::91bf:dbee:3230:e1f1:63998] [PvELi0gOHwU] wsgi_logger.c(147):   File "C:\\cdb\\CONTACT_Elements_Server_15.3.13\\cdb\\python\\cdb\\wsgi\\dispatcher\\helpers.py", line 468, in __call__
[2019-01-25 09:43:05.725139] [wsgi:error] [pid 11800:tid 3008] [client fe80::91bf:dbee:3230:e1f1:63998] [PvELi0gOHwU] wsgi_logger.c(147):     return self.app(environ, start_response)
[2019-01-25 09:43:05.725139] [wsgi:error] [pid 11800:tid 3008] [client fe80::91bf:dbee:3230:e1f1:63998] [PvELi0gOHwU] wsgi_logger.c(147):   File "C:\\cdb\\CONTACT_Elements_Server_15.3.13\\cdb\\python\\cdb\\wsgi\\dispatcher\\helpers.py", line 552, in __call__
[2019-01-25 09:43:05.725139] [wsgi:error] [pid 11800:tid 3008] [client fe80::91bf:dbee:3230:e1f1:63998] [PvELi0gOHwU] wsgi_logger.c(147):     return self.app(env, start_response)
[2019-01-25 09:43:05.725139] [wsgi:error] [pid 11800:tid 3008] [client fe80::91bf:dbee:3230:e1f1:63998] [PvELi0gOHwU] wsgi_logger.c(147):   File "C:\\cdb\\CONTACT_Elements_Server_15.3.13\\cdb\\python\\cdb\\wsgi\\middleware.py", line 505, in __call__
[2019-01-25 09:43:05.725139] [wsgi:error] [pid 11800:tid 3008] [client fe80::91bf:dbee:3230:e1f1:63998] [PvELi0gOHwU] wsgi_logger.c(147):     return self.app(environ, modified_start_response)
[2019-01-25 09:43:05.725139] [wsgi:error] [pid 11800:tid 3008] [client fe80::91bf:dbee:3230:e1f1:63998] [PvELi0gOHwU] wsgi_logger.c(147):   File "C:\\cdb\\CONTACT_Elements_Server_15.3.13\\cdb\\python\\cdb\\wsgi\\middleware.py", line 414, in __call__
[2019-01-25 09:43:05.726142] [wsgi:error] [pid 11800:tid 3008] [client fe80::91bf:dbee:3230:e1f1:63998] [PvELi0gOHwU] wsgi_logger.c(147):     return self.app(environ, start_response)
[2019-01-25 09:43:05.726142] [wsgi:error] [pid 11800:tid 3008] [client fe80::91bf:dbee:3230:e1f1:63998] [PvELi0gOHwU] wsgi_logger.c(147):   File "C:\\cdb\\CONTACT_Elements_Server_15.3.13\\cdb\\python\\cdb\\wsgi\\middleware.py", line 899, in __call__
[2019-01-25 09:43:05.726142] [wsgi:error] [pid 11800:tid 3008] [client fe80::91bf:dbee:3230:e1f1:63998] [PvELi0gOHwU] wsgi_logger.c(147):     return self.app(env, start_response)
[2019-01-25 09:43:05.726142] [wsgi:error] [pid 11800:tid 3008] [client fe80::91bf:dbee:3230:e1f1:63998] [PvELi0gOHwU] wsgi_logger.c(147):   File "C:\\cdb\\CONTACT_Elements_Server_15.3.13\\cdb\\python\\cdb\\wsgi\\middleware.py", line 456, in __call__
[2019-01-25 09:43:05.726142] [wsgi:error] [pid 11800:tid 3008] [client fe80::91bf:dbee:3230:e1f1:63998] [PvELi0gOHwU] wsgi_logger.c(147):     return self._get_proxy(host, port)(local_environ, start_response)
[2019-01-25 09:43:05.726142] [wsgi:error] [pid 11800:tid 3008] [client fe80::91bf:dbee:3230:e1f1:63998] [PvELi0gOHwU] wsgi_logger.c(147):   File "C:\\cdb\\CONTACT_Elements_Server_15.3.13\\cdb\\python\\cdb\\wsgi\\proxy.py", line 358, in __call__
[2019-01-25 09:43:05.741182] [wsgi:error] [pid 11800:tid 3008] [client fe80::91bf:dbee:3230:e1f1:63998] [PvELi0gOHwU] wsgi_logger.c(147):     self.handle_call(my_environ, uri, streamer)
[2019-01-25 09:43:05.741182] [wsgi:error] [pid 11800:tid 3008] [client fe80::91bf:dbee:3230:e1f1:63998] [PvELi0gOHwU] wsgi_logger.c(147):   File "C:\\cdb\\CONTACT_Elements_Server_15.3.13\\cdb\\python\\cdb\\wsgi\\proxy.py", line 276, in handle_call
[2019-01-25 09:43:05.742185] [wsgi:error] [pid 11800:tid 3008] [client fe80::91bf:dbee:3230:e1f1:63998] [PvELi0gOHwU] wsgi_logger.c(147):     if "perform() is currently running" in e.args[0]:
[2019-01-25 09:43:05.742185] [wsgi:error] [pid 11800:tid 3008] [client fe80::91bf:dbee:3230:e1f1:63998] [PvELi0gOHwU] wsgi_logger.c(147): TypeError: argument of type 'int' is not iterable
[2019-01-25 09:43:09.047976] [wsgi:error] [pid 11800:tid 3008] [client fe80::91bf:dbee:3230:e1f1:64025] [6HJbi2hQGxo] wsgi_logger.c(147): [ERROR] Could not connect to worker for user 'caddok' at port 62538!
[2019-01-25 09:52:53.216708] [wsgi:error] [pid 11800:tid 3008] [client fe80::91bf:dbee:3230:e1f1:54516] [BYA/rnhwGxo] wsgi_logger.c(147): [ERROR] Failed to get worker_host/port from session. PATH: /server/__keep_alive__ LOGIN: caddok
[2019-01-25 09:52:53.217710] [wsgi:error] [pid 11800:tid 3008] [client fe80::91bf:dbee:3230:e1f1:54516] [BYA/rnhwGxo] wsgi_logger.c(147): [ERROR] Could not connect to worker for user 'caddok' at port unknown!
[2019-01-25 10:02:53.245374] [wsgi:error] [pid 11800:tid 3008] [client fe80::91bf:dbee:3230:e1f1:54733] [TjUD0kgOHwU] wsgi_logger.c(147): [ERROR] Failed to get worker_host/port from session. PATH: /server/__keep_alive__ LOGIN: caddok
[2019-01-25 10:02:53.245374] [wsgi:error] [pid 11800:tid 3008] [client fe80::91bf:dbee:3230:e1f1:54733] [TjUD0kgOHwU] wsgi_logger.c(147): [ERROR] Could not connect to worker for user 'caddok' at port unknown!
[2019-01-25 10:12:53.261369] [wsgi:error] [pid 11800:tid 3008] [client fe80::91bf:dbee:3230:e1f1:54934] [QMLG9XhwGxo] wsgi_logger.c(147): [ERROR] Failed to get worker_host/port from session. PATH: /server/__keep_alive__ LOGIN: caddok
[2019-01-25 10:12:53.261369] [wsgi:error] [pid 11800:tid 3008] [client fe80::91bf:dbee:3230:e1f1:54934] [QMLG9XhwGxo] wsgi_logger.c(147): [ERROR] Could not connect to worker for user 'caddok' at port unknown!
[2019-01-25 10:22:53.288421] [wsgi:error] [pid 11800:tid 3008] [client fe80::91bf:dbee:3230:e1f1:55132] [il6KGUkOHwU] wsgi_logger.c(147): [ERROR] Failed to get worker_host/port from session. PATH: /server/__keep_alive__ LOGIN: caddok
[2019-01-25 10:22:53.289424] [wsgi:error] [pid 11800:tid 3008] [client fe80::91bf:dbee:3230:e1f1:55132] [il6KGUkOHwU] wsgi_logger.c(147): [ERROR] Could not connect to worker for user 'caddok' at port unknown!
[2019-01-25 10:32:53.306504] [wsgi:error] [pid 11800:tid 3008] [client fe80::91bf:dbee:3230:e1f1:55342] [B/dNPXlwGxo] wsgi_logger.c(147): [ERROR] Failed to get worker_host/port from session. PATH: /server/__keep_alive__ LOGIN: caddok
[2019-01-25 10:32:53.306504] [wsgi:error] [pid 11800:tid 3008] [client fe80::91bf:dbee:3230:e1f1:55342] [B/dNPXlwGxo] wsgi_logger.c(147): [ERROR] Could not connect to worker for user 'caddok' at port unknown!
[2019-01-25 10:42:53.320995] [wsgi:error] [pid 11800:tid 3008] [client fe80::91bf:dbee:3230:e1f1:55531] [YXkRYUkOHwU] wsgi_logger.c(147): [ERROR] Failed to get worker_host/port from session. PATH: /server/__keep_alive__ LOGIN: caddok
[2019-01-25 10:42:53.320995] [wsgi:error] [pid 11800:tid 3008] [client fe80::91bf:dbee:3230:e1f1:55531] [YXkRYUkOHwU] wsgi_logger.c(147): [ERROR] Could not connect to worker for user 'caddok' at port unknown!
[2019-01-25 10:52:53.342776] [wsgi:error] [pid 11800:tid 3008] [client fe80::91bf:dbee:3230:e1f1:55053] [mhTVhHlwGxo] wsgi_logger.c(147): [ERROR] Failed to get worker_host/port from session. PATH: /server/__keep_alive__ LOGIN: caddok
[2019-01-25 10:52:53.342776] [wsgi:error] [pid 11800:tid 3008] [client fe80::91bf:dbee:3230:e1f1:55053] [mhTVhHlwGxo] wsgi_logger.c(147): [ERROR] Could not connect to worker for user 'caddok' at port unknown!
[2019-01-25 11:02:53.357859] [wsgi:error] [pid 11800:tid 3008] [client fe80::91bf:dbee:3230:e1f1:55253] [PJWYqEkOHwU] wsgi_logger.c(147): [ERROR] Failed to get worker_host/port from session. PATH: /server/__keep_alive__ LOGIN: caddok
[2019-01-25 11:02:53.357859] [wsgi:error] [pid 11800:tid 3008] [client fe80::91bf:dbee:3230:e1f1:55253] [PJWYqEkOHwU] wsgi_logger.c(147): [ERROR] Could not connect to worker for user 'caddok' at port unknown!
[2019-01-25 11:12:53.373384] [wsgi:error] [pid 11800:tid 3008] [client fe80::91bf:dbee:3230:e1f1:55453] [DxRczHlwGxo] wsgi_logger.c(147): [ERROR] Failed to get worker_host/port from session. PATH: /server/__keep_alive__ LOGIN: caddok
[2019-01-25 11:12:53.373384] [wsgi:error] [pid 11800:tid 3008] [client fe80::91bf:dbee:3230:e1f1:55453] [DxRczHlwGxo] wsgi_logger.c(147): [ERROR] Could not connect to worker for user 'caddok' at port unknown!
[2019-01-25 11:22:53.390787] [wsgi:error] [pid 11800:tid 3008] [client fe80::91bf:dbee:3230:e1f1:55665] [AqIf8AkrZxo] wsgi_logger.c(147): [ERROR] Failed to get worker_host/port from session. PATH: /server/__keep_alive__ LOGIN: caddok
[2019-01-25 11:22:53.390787] [wsgi:error] [pid 11800:tid 3008] [client fe80::91bf:dbee:3230:e1f1:55665] [AqIf8AkrZxo] wsgi_logger.c(147): [ERROR] Could not connect to worker for user 'caddok' at port unknown!
[2019-01-25 11:32:53.405578] [wsgi:error] [pid 11800:tid 3008] [client fe80::91bf:dbee:3230:e1f1:55874] [4B3jE6rNHwU] wsgi_logger.c(147): [ERROR] Failed to get worker_host/port from session. PATH: /server/__keep_alive__ LOGIN: caddok
[2019-01-25 11:32:53.406579] [wsgi:error] [pid 11800:tid 3008] [client fe80::91bf:dbee:3230:e1f1:55874] [4B3jE6rNHwU] wsgi_logger.c(147): [ERROR] Could not connect to worker for user 'caddok' at port unknown!
[2019-01-25 11:42:53.437442] [wsgi:error] [pid 11800:tid 3008] [client fe80::91bf:dbee:3230:e1f1:56073] [18imNworZxo] wsgi_logger.c(147): [ERROR] Failed to get worker_host/port from session. PATH: /server/__keep_alive__ LOGIN: caddok
[2019-01-25 11:42:53.437442] [wsgi:error] [pid 11800:tid 3008] [client fe80::91bf:dbee:3230:e1f1:56073] [18imNworZxo] wsgi_logger.c(147): [ERROR] Could not connect to worker for user 'caddok' at port unknown!
[2019-01-25 11:52:53.478688] [wsgi:error] [pid 11800:tid 3008] [client fe80::91bf:dbee:3230:e1f1:56279] [4rNqW6rNHwU] wsgi_logger.c(147): [ERROR] Failed to get worker_host/port from session. PATH: /server/__keep_alive__ LOGIN: caddok
[2019-01-25 11:52:53.479689] [wsgi:error] [pid 11800:tid 3008] [client fe80::91bf:dbee:3230:e1f1:56279] [4rNqW6rNHwU] wsgi_logger.c(147): [ERROR] Could not connect to worker for user 'caddok' at port unknown!
[2019-01-25 12:02:53.509118] [wsgi:error] [pid 11800:tid 3008] [client fe80::91bf:dbee:3230:e1f1:56476] [w3AufworZxo] wsgi_logger.c(147): [ERROR] Failed to get worker_host/port from session. PATH: /server/__keep_alive__ LOGIN: caddok
[2019-01-25 12:02:53.510119] [wsgi:error] [pid 11800:tid 3008] [client fe80::91bf:dbee:3230:e1f1:56476] [w3AufworZxo] wsgi_logger.c(147): [ERROR] Could not connect to worker for user 'caddok' at port unknown!
[2019-01-25 12:12:53.536912] [wsgi:error] [pid 11800:tid 3008] [client fe80::91bf:dbee:3230:e1f1:56664] [JCvyoqrNHwU] wsgi_logger.c(147): [ERROR] Failed to get worker_host/port from session. PATH: /server/__keep_alive__ LOGIN: caddok
[2019-01-25 12:12:53.537913] [wsgi:error] [pid 11800:tid 3008] [client fe80::91bf:dbee:3230:e1f1:56664] [JCvyoqrNHwU] wsgi_logger.c(147): [ERROR] Could not connect to worker for user 'caddok' at port unknown!
[2019-01-25 12:22:53.569450] [wsgi:error] [pid 11800:tid 3008] [client fe80::91bf:dbee:3230:e1f1:56874] [aei1xgorZxo] wsgi_logger.c(147): [ERROR] Failed to get worker_host/port from session. PATH: /server/__keep_alive__ LOGIN: caddok
[2019-01-25 12:22:53.569450] [wsgi:error] [pid 11800:tid 3008] [client fe80::91bf:dbee:3230:e1f1:56874] [aei1xgorZxo] wsgi_logger.c(147): [ERROR] Could not connect to worker for user 'caddok' at port unknown!
[2019-01-25 12:32:53.601159] [wsgi:error] [pid 11800:tid 3008] [client fe80::91bf:dbee:3230:e1f1:57064] [kqZ56qrNHwU] wsgi_logger.c(147): [ERROR] Failed to get worker_host/port from session. PATH: /server/__keep_alive__ LOGIN: caddok
[2019-01-25 12:32:53.601159] [wsgi:error] [pid 11800:tid 3008] [client fe80::91bf:dbee:3230:e1f1:57064] [kqZ56qrNHwU] wsgi_logger.c(147): [ERROR] Could not connect to worker for user 'caddok' at port unknown!
[2019-01-25 12:42:53.630798] [wsgi:error] [pid 11800:tid 3008] [client fe80::91bf:dbee:3230:e1f1:57255] [Img9DgsrZxo] wsgi_logger.c(147): [ERROR] Failed to get worker_host/port from session. PATH: /server/__keep_alive__ LOGIN: caddok
[2019-01-25 12:42:53.631800] [wsgi:error] [pid 11800:tid 3008] [client fe80::91bf:dbee:3230:e1f1:57255] [Img9DgsrZxo] wsgi_logger.c(147): [ERROR] Could not connect to worker for user 'caddok' at port unknown!
[2019-01-25 12:52:53.682959] [wsgi:error] [pid 11800:tid 3008] [client fe80::91bf:dbee:3230:e1f1:54230] [WGIBMqvNHwU] wsgi_logger.c(147): [ERROR] Failed to get worker_host/port from session. PATH: /server/__keep_alive__ LOGIN: caddok
[2019-01-25 12:52:53.683954] [wsgi:error] [pid 11800:tid 3008] [client fe80::91bf:dbee:3230:e1f1:54230] [WGIBMqvNHwU] wsgi_logger.c(147): [ERROR] Could not connect to worker for user 'caddok' at port unknown!
[2019-01-25 13:02:53.700710] [wsgi:error] [pid 11800:tid 3008] [client fe80::91bf:dbee:3230:e1f1:54433] [4hHFVQsrZxo] wsgi_logger.c(147): [ERROR] Failed to get worker_host/port from session. PATH: /server/__keep_alive__ LOGIN: caddok
[2019-01-25 13:02:53.701712] [wsgi:error] [pid 11800:tid 3008] [client fe80::91bf:dbee:3230:e1f1:54433] [4hHFVQsrZxo] wsgi_logger.c(147): [ERROR] Could not connect to worker for user 'caddok' at port unknown!
[2019-01-25 13:12:53.721176] [wsgi:error] [pid 11800:tid 3008] [client fe80::91bf:dbee:3230:e1f1:54646] [nKaIeavNHwU] wsgi_logger.c(147): [ERROR] Failed to get worker_host/port from session. PATH: /server/__keep_alive__ LOGIN: caddok
[2019-01-25 13:12:53.721176] [wsgi:error] [pid 11800:tid 3008] [client fe80::91bf:dbee:3230:e1f1:54646] [nKaIeavNHwU] wsgi_logger.c(147): [ERROR] Could not connect to worker for user 'caddok' at port unknown!
[2019-01-25 13:22:53.736043] [wsgi:error] [pid 11800:tid 3008] [client fe80::91bf:dbee:3230:e1f1:54846] [bitMnQsrZxo] wsgi_logger.c(147): [ERROR] Failed to get worker_host/port from session. PATH: /server/__keep_alive__ LOGIN: caddok
[2019-01-25 13:22:53.736043] [wsgi:error] [pid 11800:tid 3008] [client fe80::91bf:dbee:3230:e1f1:54846] [bitMnQsrZxo] wsgi_logger.c(147): [ERROR] Could not connect to worker for user 'caddok' at port unknown!
[2019-01-25 13:32:53.751204] [wsgi:error] [pid 11800:tid 3008] [client fe80::91bf:dbee:3230:e1f1:55074] [+qsPwavNHwU] wsgi_logger.c(147): [ERROR] Failed to get worker_host/port from session. PATH: /server/__keep_alive__ LOGIN: caddok
[2019-01-25 13:32:53.752207] [wsgi:error] [pid 11800:tid 3008] [client fe80::91bf:dbee:3230:e1f1:55074] [+qsPwavNHwU] wsgi_logger.c(147): [ERROR] Could not connect to worker for user 'caddok' at port unknown!
[2019-01-25 13:42:53.770391] [wsgi:error] [pid 11800:tid 3008] [client fe80::91bf:dbee:3230:e1f1:55306] [AjnT5AsrZxo] wsgi_logger.c(147): [ERROR] Failed to get worker_host/port from session. PATH: /server/__keep_alive__ LOGIN: caddok
[2019-01-25 13:42:53.770391] [wsgi:error] [pid 11800:tid 3008] [client fe80::91bf:dbee:3230:e1f1:55306] [AjnT5AsrZxo] wsgi_logger.c(147): [ERROR] Could not connect to worker for user 'caddok' at port unknown!
[2019-01-25 13:52:53.785697] [wsgi:error] [pid 11800:tid 3008] [client fe80::91bf:dbee:3230:e1f1:55509] [osKWCKzNHwU] wsgi_logger.c(147): [ERROR] Failed to get worker_host/port from session. PATH: /server/__keep_alive__ LOGIN: caddok
[2019-01-25 13:52:53.785697] [wsgi:error] [pid 11800:tid 3008] [client fe80::91bf:dbee:3230:e1f1:55509] [osKWCKzNHwU] wsgi_logger.c(147): [ERROR] Could not connect to worker for user 'caddok' at port unknown!
[2019-01-25 14:02:53.801135] [wsgi:error] [pid 11800:tid 3008] [client fe80::91bf:dbee:3230:e1f1:55713] [BEFaLAwrZxo] wsgi_logger.c(147): [ERROR] Failed to get worker_host/port from session. PATH: /server/__keep_alive__ LOGIN: caddok
[2019-01-25 14:02:53.801135] [wsgi:error] [pid 11800:tid 3008] [client fe80::91bf:dbee:3230:e1f1:55713] [BEFaLAwrZxo] wsgi_logger.c(147): [ERROR] Could not connect to worker for user 'caddok' at port unknown!
[2019-01-25 14:12:53.825357] [wsgi:error] [pid 11800:tid 3008] [client fe80::91bf:dbee:3230:e1f1:56004] [4c4dUOyv8hg] wsgi_logger.c(147): [ERROR] Failed to get worker_host/port from session. PATH: /server/__keep_alive__ LOGIN: caddok
[2019-01-25 14:12:53.825357] [wsgi:error] [pid 11800:tid 3008] [client fe80::91bf:dbee:3230:e1f1:56004] [4c4dUOyv8hg] wsgi_logger.c(147): [ERROR] Could not connect to worker for user 'caddok' at port unknown!
[2019-01-25 14:22:53.841508] [wsgi:error] [pid 11800:tid 3008] [client fe80::91bf:dbee:3230:e1f1:56218] [o27hc2xQGxo] wsgi_logger.c(147): [ERROR] Failed to get worker_host/port from session. PATH: /server/__keep_alive__ LOGIN: caddok
[2019-01-25 14:22:53.842511] [wsgi:error] [pid 11800:tid 3008] [client fe80::91bf:dbee:3230:e1f1:56218] [o27hc2xQGxo] wsgi_logger.c(147): [ERROR] Could not connect to worker for user 'caddok' at port unknown!
[2019-01-25 14:32:53.867167] [wsgi:error] [pid 11800:tid 3008] [client fe80::91bf:dbee:3230:e1f1:56411] [PxGll+yv8hg] wsgi_logger.c(147): [ERROR] Failed to get worker_host/port from session. PATH: /server/__keep_alive__ LOGIN: caddok
[2019-01-25 14:32:53.868170] [wsgi:error] [pid 11800:tid 3008] [client fe80::91bf:dbee:3230:e1f1:56411] [PxGll+yv8hg] wsgi_logger.c(147): [ERROR] Could not connect to worker for user 'caddok' at port unknown!
[2019-01-25 14:36:25.333077] [wsgi:error] [pid 11800:tid 3008] [client fe80::91bf:dbee:3230:e1f1:56484] [7MQ/pOyv8hg] wsgi_logger.c(147): [ERROR] Failed to get worker_host/port from session. PATH: /server/invoke LOGIN: caddok
[2019-01-25 14:36:25.333077] [wsgi:error] [pid 11800:tid 3008] [client fe80::91bf:dbee:3230:e1f1:56484] [7MQ/pOyv8hg] wsgi_logger.c(147): [ERROR] Could not connect to worker for user 'caddok' at port unknown!
[2019-01-25 14:36:25.733729] [wsgi:error] [pid 11800:tid 3000] [client fe80::91bf:dbee:3230:e1f1:56486] [q+pFpBxLZxo] wsgi_logger.c(147): [ERROR] Failed to get worker_host/port from session. PATH: /server/invoke LOGIN: caddok
[2019-01-25 14:36:25.734228] [wsgi:error] [pid 11800:tid 3000] [client fe80::91bf:dbee:3230:e1f1:56486] [q+pFpBxLZxo] wsgi_logger.c(147): [ERROR] Could not connect to worker for user 'caddok' at port unknown!
[2019-01-25 14:36:25.788381] [wsgi:error] [pid 11800:tid 2976] [client fe80::91bf:dbee:3230:e1f1:56487] [Y7ZGpHxwGxo] wsgi_logger.c(147): [ERROR] Failed to get worker_host/port from session. PATH: /server/invoke LOGIN: caddok
[2019-01-25 14:36:25.788381] [wsgi:error] [pid 11800:tid 2976] [client fe80::91bf:dbee:3230:e1f1:56487] [Y7ZGpHxwGxo] wsgi_logger.c(147): [ERROR] Could not connect to worker for user 'caddok' at port unknown!
[2019-01-25 14:36:25.802923] [wsgi:error] [pid 11800:tid 2980] [client fe80::91bf:dbee:3230:e1f1:56488] [8/hGpEwQGxo] wsgi_logger.c(147): [ERROR] Failed to get worker_host/port from session. PATH: /server/invoke LOGIN: caddok
[2019-01-25 14:36:25.803424] [wsgi:error] [pid 11800:tid 2980] [client fe80::91bf:dbee:3230:e1f1:56488] [8/hGpEwQGxo] wsgi_logger.c(147): [ERROR] Could not connect to worker for user 'caddok' at port unknown!
[2019-01-25 14:36:25.822472] [wsgi:error] [pid 11800:tid 2984] [client fe80::91bf:dbee:3230:e1f1:56489] [4StHpAwrZxo] wsgi_logger.c(147): [ERROR] Failed to get worker_host/port from session. PATH: /server/invoke LOGIN: caddok
[2019-01-25 14:36:25.822976] [wsgi:error] [pid 11800:tid 2984] [client fe80::91bf:dbee:3230:e1f1:56489] [4StHpAwrZxo] wsgi_logger.c(147): [ERROR] Could not connect to worker for user 'caddok' at port unknown!
[2019-01-25 14:36:25.854033] [wsgi:error] [pid 11800:tid 2988] [client fe80::91bf:dbee:3230:e1f1:56490] [n8BHpGxQGxo] wsgi_logger.c(147): [ERROR] Failed to get worker_host/port from session. PATH: /server/__quit__ LOGIN: caddok
[2019-01-25 14:36:33.987708] [mpm_winnt:notice] [pid 14236:tid 568] mpm_winnt.c(811): AH00422: Parent: Received shutdown signal -- Shutting down the server.
[2019-01-25 14:36:35.991236] [mpm_winnt:notice] [pid 11800:tid 892] child.c(1252): AH00364: Child: All worker threads have exited.
[2019-01-25 14:36:36.278557] [mpm_winnt:notice] [pid 14236:tid 568] mpm_winnt.c(901): AH00430: Parent: Child process 11800 exited successfully.
[2019-01-25 15:07:26.330150] [mpm_winnt:notice] [pid 13380:tid 596] mpm_winnt.c(1730): AH00455: Apache/2.4.33 (Win64) OpenSSL/1.0.2m mod_wsgi/4.5.15 Python/2.7 configured -- resuming normal operations
[2019-01-25 15:07:26.341681] [mpm_winnt:notice] [pid 13380:tid 596] mpm_winnt.c(1733): AH00456: Server built: May 17 2018 13:03:53
[2019-01-25 15:07:26.341681] [core:notice] [pid 13380:tid 596] log.c(1560): AH00094: Command line: 'C:\\cdb\\CONTACT_Elements_Server_15.3.13\\httpd.exe -d C:/cdb/CONTACT_Elements_Server_15.3.13 -d C:/cdb/CONTACT_Elements_Server_15.3.13 -f C:/cdb/rbei/tmp/httpngusqk.conf -D WIN32 -D USE_SSL -D USE_CACHE'
[2019-01-25 15:07:26.406352] [mpm_winnt:notice] [pid 13380:tid 596] mpm_winnt.c(649): AH00418: Parent: Created child process 10084
[2019-01-25 15:07:35.155116] [mpm_winnt:notice] [pid 10084:tid 760] child.c(968): AH00354: Child: Starting 256 worker threads.
[2019-01-25 15:07:40.240140] [cache:error] [pid 10084:tid 3040] [client fe80::91bf:dbee:3230:e1f1:56766] [gDcAFF1TOwU] [(OS 5)Access is denied.  ] cache_util.c(355): AH00779: Could not stat a cache lock file: C:/cdb/rbei/etcd/mod_cache-lock/s/j/sjyc@B3yr4kSljHqiiW0Dg
[2019-01-25 15:08:02.638758] [cache:error] [pid 10084:tid 3032] [client fe80::91bf:dbee:3230:e1f1:56787] [8WNWFX0SNQU] [(OS 5)Access is denied.  ] cache_util.c(355): AH00779: Could not stat a cache lock file: C:/cdb/rbei/etcd/mod_cache-lock/s/j/sjyc@B3yr4kSljHqiiW0Dg
[2019-01-25 15:08:02.640763] [cache:error] [pid 10084:tid 3032] [client fe80::91bf:dbee:3230:e1f1:56787] [8WNWFX0SNQU] [(OS 5)Access is denied.  ] cache_util.c(355): AH00779: Could not stat a cache lock file: C:/cdb/rbei/etcd/mod_cache-lock/s/j/sjyc@B3yr4kSljHqiiW0Dg
[2019-01-25 15:08:07.686180] [cache:error] [pid 10084:tid 3028] [client fe80::91bf:dbee:3230:e1f1:56788] [mmCjFf2JzgU] [(OS 5)Access is denied.  ] cache_util.c(355): AH00779: Could not stat a cache lock file: C:/cdb/rbei/etcd/mod_cache-lock/s/j/sjyc@B3yr4kSljHqiiW0Dg
[2019-01-25 15:08:07.687685] [cache:error] [pid 10084:tid 3028] [client fe80::91bf:dbee:3230:e1f1:56788] [mmCjFf2JzgU] [(OS 5)Access is denied.  ] cache_util.c(355): AH00779: Could not stat a cache lock file: C:/cdb/rbei/etcd/mod_cache-lock/s/j/sjyc@B3yr4kSljHqiiW0Dg
[2019-01-25 15:08:13.003319] [mpm_winnt:notice] [pid 13380:tid 596] mpm_winnt.c(811): AH00422: Parent: Received shutdown signal -- Shutting down the server.
[2019-01-25 15:12:40.599500] [mpm_winnt:notice] [pid 14200:tid 540] mpm_winnt.c(1730): AH00455: Apache/2.4.33 (Win64) OpenSSL/1.0.2m mod_wsgi/4.5.15 Python/2.7 configured -- resuming normal operations
[2019-01-25 15:12:40.613038] [mpm_winnt:notice] [pid 14200:tid 540] mpm_winnt.c(1733): AH00456: Server built: May 17 2018 13:03:53
[2019-01-25 15:12:40.613038] [core:notice] [pid 14200:tid 540] log.c(1560): AH00094: Command line: 'C:\\cdb\\CONTACT_Elements_Server_15.3.13\\httpd.exe -d C:/cdb/CONTACT_Elements_Server_15.3.13 -d C:/cdb/CONTACT_Elements_Server_15.3.13 -f C:/cdb/rbei/tmp/http52aqvy.conf -D WIN32 -D USE_SSL -D USE_CACHE'
[2019-01-25 15:12:40.651639] [mpm_winnt:notice] [pid 14200:tid 540] mpm_winnt.c(649): AH00418: Parent: Created child process 7100
Apache server shutdown initiated...
nnt:notice] [pid 7100:tid 132] child.c(968): AH00354: Child: Starting 256 worker threads.
[2019-01-25 15:13:03.110873] [cache:error] [pid 7100:tid 3012] [client fe80::91bf:dbee:3230:e1f1:56880] [7uY+J50JyAQ] [(OS 5)Access is denied.  ] cache_util.c(355): AH00779: Could not stat a cache lock file: C:/cdb/rbei/etcd/mod_cache-lock/s/j/sjyc@B3yr4kSljHqiiW0Dg
[2019-01-25 15:13:18.289736] [cache:error] [pid 7100:tid 3004] [client fe80::91bf:dbee:3230:e1f1:56883] [CHklKN2JywQ] [(OS 5)Access is denied.  ] cache_util.c(355): AH00779: Could not stat a cache lock file: C:/cdb/rbei/etcd/mod_cache-lock/s/j/sjyc@B3yr4kSljHqiiW0Dg
[2019-01-25 15:13:18.354408] [cache:error] [pid 7100:tid 3004] [client fe80::91bf:dbee:3230:e1f1:56883] [CHklKN2JywQ] [(OS 5)Access is denied.  ] cache_util.c(355): AH00779: Could not stat a cache lock file: C:/cdb/rbei/etcd/mod_cache-lock/s/j/sjyc@B3yr4kSljHqiiW0Dg
[2019-01-25 15:13:23.228871] [cache:error] [pid 7100:tid 3000] [client fe80::91bf:dbee:3230:e1f1:56902] [HDNyKO15uQU] [(OS 5)Access is denied.  ] cache_util.c(355): AH00779: Could not stat a cache lock file: C:/cdb/rbei/etcd/mod_cache-lock/s/j/sjyc@B3yr4kSljHqiiW0Dg
[2019-01-25 15:13:23.232379] [cache:error] [pid 7100:tid 3000] [client fe80::91bf:dbee:3230:e1f1:56902] [HDNyKO15uQU] [(OS 5)Access is denied.  ] cache_util.c(355): AH00779: Could not stat a cache lock file: C:/cdb/rbei/etcd/mod_cache-lock/s/j/sjyc@B3yr4kSljHqiiW0Dg
[2019-01-25 15:13:28.370542] [cache:error] [pid 7100:tid 2996] [client fe80::91bf:dbee:3230:e1f1:56906] [uanAKG16tgU] [(OS 5)Access is denied.  ] cache_util.c(355): AH00779: Could not stat a cache lock file: C:/cdb/rbei/etcd/mod_cache-lock/s/j/sjyc@B3yr4kSljHqiiW0Dg
[2019-01-25 15:13:28.374052] [cache:error] [pid 7100:tid 2996] [client fe80::91bf:dbee:3230:e1f1:56906] [uanAKG16tgU] [(OS 5)Access is denied.  ] cache_util.c(355): AH00779: Could not stat a cache lock file: C:/cdb/rbei/etcd/mod_cache-lock/s/j/sjyc@B3yr4kSljHqiiW0Dg
[2019-01-25 15:13:33.399415] [cache:error] [pid 7100:tid 2992] [client fe80::91bf:dbee:3230:e1f1:56907] [uGcNKQ26tgU] [(OS 5)Access is denied.  ] cache_util.c(355): AH00779: Could not stat a cache lock file: C:/cdb/rbei/etcd/mod_cache-lock/s/j/sjyc@B3yr4kSljHqiiW0Dg
[2019-01-25 15:13:33.399918] [cache:error] [pid 7100:tid 2992] [client fe80::91bf:dbee:3230:e1f1:56907] [uGcNKQ26tgU] [(OS 5)Access is denied.  ] cache_util.c(355): AH00779: Could not stat a cache lock file: C:/cdb/rbei/etcd/mod_cache-lock/s/j/sjyc@B3yr4kSljHqiiW0Dg
[2019-01-25 15:13:38.474911] [cache:error] [pid 7100:tid 2988] [client fe80::91bf:dbee:3230:e1f1:56911] [K8xaKQ27tAU] [(OS 5)Access is denied.  ] cache_util.c(355): AH00779: Could not stat a cache lock file: C:/cdb/rbei/etcd/mod_cache-lock/s/j/sjyc@B3yr4kSljHqiiW0Dg
[2019-01-25 15:13:38.476917] [cache:error] [pid 7100:tid 2988] [client fe80::91bf:dbee:3230:e1f1:56911] [K8xaKQ27tAU] [(OS 5)Access is denied.  ] cache_util.c(355): AH00779: Could not stat a cache lock file: C:/cdb/rbei/etcd/mod_cache-lock/s/j/sjyc@B3yr4kSljHqiiW0Dg
[2019-01-25 15:13:43.492755] [cache:error] [pid 7100:tid 2984] [client fe80::91bf:dbee:3230:e1f1:56917] [yWynKW3KvxY] [(OS 5)Access is denied.  ] cache_util.c(355): AH00779: Could not stat a cache lock file: C:/cdb/rbei/etcd/mod_cache-lock/s/j/sjyc@B3yr4kSljHqiiW0Dg
[2019-01-25 15:13:43.495763] [cache:error] [pid 7100:tid 2984] [client fe80::91bf:dbee:3230:e1f1:56917] [yWynKW3KvxY] [(OS 5)Access is denied.  ] cache_util.c(355): AH00779: Could not stat a cache lock file: C:/cdb/rbei/etcd/mod_cache-lock/s/j/sjyc@B3yr4kSljHqiiW0Dg
[2019-01-25 15:13:58.508183] [cache:error] [pid 7100:tid 2980] [client fe80::91bf:dbee:3230:e1f1:56926] [14iMKt3ruhY] [(OS 5)Access is denied.  ] cache_util.c(355): AH00779: Could not stat a cache lock file: C:/cdb/rbei/etcd/mod_cache-lock/s/j/sjyc@B3yr4kSljHqiiW0Dg
[2019-01-25 15:13:58.509689] [cache:error] [pid 7100:tid 2980] [client fe80::91bf:dbee:3230:e1f1:56926] [14iMKt3ruhY] [(OS 5)Access is denied.  ] cache_util.c(355): AH00779: Could not stat a cache lock file: C:/cdb/rbei/etcd/mod_cache-lock/s/j/sjyc@B3yr4kSljHqiiW0Dg
[2019-01-25 15:14:03.543573] [cache:error] [pid 7100:tid 2976] [client fe80::91bf:dbee:3230:e1f1:56927] [tkzZKm1LKxc] [(OS 5)Access is denied.  ] cache_util.c(355): AH00779: Could not stat a cache lock file: C:/cdb/rbei/etcd/mod_cache-lock/s/j/sjyc@B3yr4kSljHqiiW0Dg
[2019-01-25 15:14:03.546080] [cache:error] [pid 7100:tid 2976] [client fe80::91bf:dbee:3230:e1f1:56927] [tkzZKm1LKxc] [(OS 5)Access is denied.  ] cache_util.c(355): AH00779: Could not stat a cache lock file: C:/cdb/rbei/etcd/mod_cache-lock/s/j/sjyc@B3yr4kSljHqiiW0Dg
[2019-01-25 15:19:55.120931] [mpm_winnt:notice] [pid 14200:tid 540] mpm_winnt.c(811): AH00422: Parent: Received shutdown signal -- Shutting down the server.
[2019-01-25 15:19:57.147639] [mpm_winnt:notice] [pid 7100:tid 132] child.c(1252): AH00364: Child: All worker threads have exited.
[2019-01-25 15:19:57.387988] [mpm_winnt:notice] [pid 14200:tid 540] mpm_winnt.c(901): AH00430: Parent: Child process 7100 exited successfully.
[2019-01-25 15:43:46.362761] [mpm_winnt:notice] [pid 11064:tid 544] mpm_winnt.c(1730): AH00455: Apache/2.4.33 (Win64) OpenSSL/1.0.2m mod_wsgi/4.5.15 Python/2.7 configured -- resuming normal operations
[2019-01-25 15:43:46.365771] [mpm_winnt:notice] [pid 11064:tid 544] mpm_winnt.c(1733): AH00456: Server built: May 17 2018 13:03:53
[2019-01-25 15:43:46.365771] [core:notice] [pid 11064:tid 544] log.c(1560): AH00094: Command line: 'C:\\cdb\\CONTACT_Elements_Server_15.3.13\\httpd.exe -d C:/cdb/CONTACT_Elements_Server_15.3.13 -d C:/cdb/CONTACT_Elements_Server_15.3.13 -f C:/cdb/rbei/tmp/httpovce3c.conf -D WIN32 -D USE_SSL -D USE_CACHE'
[2019-01-25 15:43:46.390307] [mpm_winnt:notice] [pid 11064:tid 544] mpm_winnt.c(649): AH00418: Parent: Created child process 11768
[2019-01-25 15:43:53.485140] [mpm_winnt:notice] [pid 11768:tid 716] child.c(968): AH00354: Child: Starting 256 worker threads.
[2019-01-25 15:43:58.544380] [cache:error] [pid 11768:tid 3076] [client fe80::91bf:dbee:3230:e1f1:62185] [McbWld3NwgQ] [(OS 5)Access is denied.  ] cache_util.c(355): AH00779: Could not stat a cache lock file: C:/cdb/rbei/etcd/mod_cache-lock/s/j/sjyc@B3yr4kSljHqiiW0Dg
[2019-01-25 15:44:18.424120] [cache:error] [pid 11768:tid 3068] [client fe80::91bf:dbee:3230:e1f1:62206] [vjYGl13NwQQ] [(OS 5)Access is denied.  ] cache_util.c(355): AH00779: Could not stat a cache lock file: C:/cdb/rbei/etcd/mod_cache-lock/s/j/sjyc@B3yr4kSljHqiiW0Dg
[2019-01-25 15:44:18.426152] [cache:error] [pid 11768:tid 3068] [client fe80::91bf:dbee:3230:e1f1:62206] [vjYGl13NwQQ] [(OS 5)Access is denied.  ] cache_util.c(355): AH00779: Could not stat a cache lock file: C:/cdb/rbei/etcd/mod_cache-lock/s/j/sjyc@B3yr4kSljHqiiW0Dg
[2019-01-25 15:44:23.460512] [cache:error] [pid 11768:tid 2560] [client fe80::91bf:dbee:3230:e1f1:62207] [4BhTl23N6AU] [(OS 5)Access is denied.  ] cache_util.c(355): AH00779: Could not stat a cache lock file: C:/cdb/rbei/etcd/mod_cache-lock/s/j/sjyc@B3yr4kSljHqiiW0Dg
[2019-01-25 15:44:23.463384] [cache:error] [pid 11768:tid 2560] [client fe80::91bf:dbee:3230:e1f1:62207] [4BhTl23N6AU] [(OS 5)Access is denied.  ] cache_util.c(355): AH00779: Could not stat a cache lock file: C:/cdb/rbei/etcd/mod_cache-lock/s/j/sjyc@B3yr4kSljHqiiW0Dg
[2019-01-25 15:44:28.670981] [mpm_winnt:notice] [pid 11064:tid 544] mpm_winnt.c(811): AH00422: Parent: Received shutdown signal -- Shutting down the server.
[2019-01-25 15:45:51.372918] [mpm_winnt:notice] [pid 10312:tid 564] mpm_winnt.c(1730): AH00455: Apache/2.4.33 (Win64) OpenSSL/1.0.2m mod_wsgi/4.5.15 Python/2.7 configured -- resuming normal operations
[2019-01-25 15:45:51.389495] [mpm_winnt:notice] [pid 10312:tid 564] mpm_winnt.c(1733): AH00456: Server built: May 17 2018 13:03:53
[2019-01-25 15:45:51.389495] [core:notice] [pid 10312:tid 564] log.c(1560): AH00094: Command line: 'C:\\cdb\\CONTACT_Elements_Server_15.3.13\\httpd.exe -d C:/cdb/CONTACT_Elements_Server_15.3.13 -d C:/cdb/CONTACT_Elements_Server_15.3.13 -f C:/cdb/rbei/tmp/httpz1asfn.conf -D WIN32 -D USE_SSL -D USE_CACHE'
[2019-01-25 15:45:51.445901] [mpm_winnt:notice] [pid 10312:tid 564] mpm_winnt.c(649): AH00418: Parent: Created child process 11628
[2019-01-25 15:46:00.010791] [mpm_winnt:notice] [pid 11628:tid 600] child.c(968): AH00354: Child: Starting 256 worker threads.
[2019-01-25 15:46:05.083888] [cache:error] [pid 11628:tid 3012] [client fe80::91bf:dbee:3230:e1f1:62264] [gnphne05kgQ] [(OS 5)Access is denied.  ] cache_util.c(355): AH00779: Could not stat a cache lock file: C:/cdb/rbei/etcd/mod_cache-lock/s/j/sjyc@B3yr4kSljHqiiW0Dg
[2019-01-25 15:46:21.876950] [cache:error] [pid 11628:tid 3004] [client fe80::91bf:dbee:3230:e1f1:62283] [X+thnv0ZkgQ] [(OS 5)Access is denied.  ] cache_util.c(355): AH00779: Could not stat a cache lock file: C:/cdb/rbei/etcd/mod_cache-lock/s/j/sjyc@B3yr4kSljHqiiW0Dg
[2019-01-25 15:46:21.895330] [cache:error] [pid 11628:tid 3004] [client fe80::91bf:dbee:3230:e1f1:62283] [X+thnv0ZkgQ] [(OS 5)Access is denied.  ] cache_util.c(355): AH00779: Could not stat a cache lock file: C:/cdb/rbei/etcd/mod_cache-lock/s/j/sjyc@B3yr4kSljHqiiW0Dg
[2019-01-25 15:46:26.895607] [cache:error] [pid 11628:tid 3000] [client fe80::91bf:dbee:3230:e1f1:62288] [6ZSunm2WpgU] [(OS 5)Access is denied.  ] cache_util.c(355): AH00779: Could not stat a cache lock file: C:/cdb/rbei/etcd/mod_cache-lock/s/j/sjyc@B3yr4kSljHqiiW0Dg
[2019-01-25 15:46:26.895607] [cache:error] [pid 11628:tid 3000] [client fe80::91bf:dbee:3230:e1f1:62288] [6ZSunm2WpgU] [(OS 5)Access is denied.  ] cache_util.c(355): AH00779: Could not stat a cache lock file: C:/cdb/rbei/etcd/mod_cache-lock/s/j/sjyc@B3yr4kSljHqiiW0Dg
[2019-01-25 15:46:32.320585] [mpm_winnt:notice] [pid 10312:tid 564] mpm_winnt.c(811): AH00422: Parent: Received shutdown signal -- Shutting down the server.
[2019-01-25 15:54:42.679637] [mpm_winnt:notice] [pid 4728:tid 188] mpm_winnt.c(1730): AH00455: Apache/2.4.33 (Win64) OpenSSL/1.0.2m mod_wsgi/4.5.15 Python/2.7 configured -- resuming normal operations
[2019-01-25 15:54:42.683694] [mpm_winnt:notice] [pid 4728:tid 188] mpm_winnt.c(1733): AH00456: Server built: May 17 2018 13:03:53
[2019-01-25 15:54:42.683694] [core:notice] [pid 4728:tid 188] log.c(1560): AH00094: Command line: 'C:\\cdb\\CONTACT_Elements_Server_15.3.13\\httpd.exe -d C:/cdb/CONTACT_Elements_Server_15.3.13 -d C:/cdb/CONTACT_Elements_Server_15.3.13 -f C:/cdb/rbei/tmp/httpmbv29y.conf -D WIN32 -D USE_SSL -D USE_CACHE'
[2019-01-25 15:54:42.722256] [mpm_winnt:notice] [pid 4728:tid 188] mpm_winnt.c(649): AH00418: Parent: Created child process 9392
Apache server interrupted...
[mpm_winnt:notice] [pid 9392:tid 624] child.c(968): AH00354: Child: Starting 256 worker threads.
[2019-01-25 15:55:07.320126] [cache:error] [pid 9392:tid 3012] [client fe80::91bf:dbee:3230:e1f1:62509] [pYizvc2lVgU] [(OS 5)Access is denied.  ] cache_util.c(355): AH00779: Could not stat a cache lock file: C:/cdb/rbei/etcd/mod_cache-lock/s/j/sjyc@B3yr4kSljHqiiW0Dg
[2019-01-25 15:55:14.605529] [cache:error] [pid 9392:tid 3004] [client fe80::91bf:dbee:3230:e1f1:62523] [db4ivk2mWQU] [(OS 5)Access is denied.  ] cache_util.c(355): AH00779: Could not stat a cache lock file: C:/cdb/rbei/etcd/mod_cache-lock/s/j/sjyc@B3yr4kSljHqiiW0Dg
[2019-01-25 15:55:14.606529] [cache:error] [pid 9392:tid 3004] [client fe80::91bf:dbee:3230:e1f1:62523] [db4ivk2mWQU] [(OS 5)Access is denied.  ] cache_util.c(355): AH00779: Could not stat a cache lock file: C:/cdb/rbei/etcd/mod_cache-lock/s/j/sjyc@B3yr4kSljHqiiW0Dg
[2019-01-25 15:55:19.853306] [cache:error] [pid 9392:tid 3000] [client fe80::91bf:dbee:3230:e1f1:62532] [1dZyvp0UWQY] [(OS 5)Access is denied.  ] cache_util.c(355): AH00779: Could not stat a cache lock file: C:/cdb/rbei/etcd/mod_cache-lock/s/j/sjyc@B3yr4kSljHqiiW0Dg
[2019-01-25 15:55:19.853306] [cache:error] [pid 9392:tid 3000] [client fe80::91bf:dbee:3230:e1f1:62532] [1dZyvp0UWQY] [(OS 5)Access is denied.  ] cache_util.c(355): AH00779: Could not stat a cache lock file: C:/cdb/rbei/etcd/mod_cache-lock/s/j/sjyc@B3yr4kSljHqiiW0Dg
[2019-01-25 15:55:24.883654] [cache:error] [pid 9392:tid 2996] [client fe80::91bf:dbee:3230:e1f1:62534] [9Zi/vo00WQY] [(OS 5)Access is denied.  ] cache_util.c(355): AH00779: Could not stat a cache lock file: C:/cdb/rbei/etcd/mod_cache-lock/s/j/sjyc@B3yr4kSljHqiiW0Dg
[2019-01-25 15:55:24.884658] [cache:error] [pid 9392:tid 2996] [client fe80::91bf:dbee:3230:e1f1:62534] [9Zi/vo00WQY] [(OS 5)Access is denied.  ] cache_util.c(355): AH00779: Could not stat a cache lock file: C:/cdb/rbei/etcd/mod_cache-lock/s/j/sjyc@B3yr4kSljHqiiW0Dg
[2019-01-25 15:55:29.911429] [cache:error] [pid 9392:tid 2992] [client fe80::91bf:dbee:3230:e1f1:62538] [ElYMv905ewY] [(OS 5)Access is denied.  ] cache_util.c(355): AH00779: Could not stat a cache lock file: C:/cdb/rbei/etcd/mod_cache-lock/s/j/sjyc@B3yr4kSljHqiiW0Dg
[2019-01-25 15:55:29.911429] [cache:error] [pid 9392:tid 2992] [client fe80::91bf:dbee:3230:e1f1:62538] [ElYMv905ewY] [(OS 5)Access is denied.  ] cache_util.c(355): AH00779: Could not stat a cache lock file: C:/cdb/rbei/etcd/mod_cache-lock/s/j/sjyc@B3yr4kSljHqiiW0Dg
[2019-01-25 15:55:44.960222] [cache:error] [pid 9392:tid 2988] [client fe80::91bf:dbee:3230:e1f1:62552] [3vPxv62ZewY] [(OS 5)Access is denied.  ] cache_util.c(355): AH00779: Could not stat a cache lock file: C:/cdb/rbei/etcd/mod_cache-lock/s/j/sjyc@B3yr4kSljHqiiW0Dg
[2019-01-25 15:55:44.961225] [cache:error] [pid 9392:tid 2988] [client fe80::91bf:dbee:3230:e1f1:62552] [3vPxv62ZewY] [(OS 5)Access is denied.  ] cache_util.c(355): AH00779: Could not stat a cache lock file: C:/cdb/rbei/etcd/mod_cache-lock/s/j/sjyc@B3yr4kSljHqiiW0Dg
[2019-01-25 15:57:15.013185] [mpm_winnt:notice] [pid 4728:tid 188] mpm_winnt.c(811): AH00422: Parent: Received shutdown signal -- Shutting down the server.
[2019-01-25 16:02:23.358129] [mpm_winnt:notice] [pid 12640:tid 852] mpm_winnt.c(1730): AH00455: Apache/2.4.33 (Win64) OpenSSL/1.0.2m mod_wsgi/4.5.15 Python/2.7 configured -- resuming normal operations
[2019-01-25 16:02:23.362346] [mpm_winnt:notice] [pid 12640:tid 852] mpm_winnt.c(1733): AH00456: Server built: May 17 2018 13:03:53
[2019-01-25 16:02:23.362346] [core:notice] [pid 12640:tid 852] log.c(1560): AH00094: Command line: 'C:\\cdb\\CONTACT_Elements_Server_15.3.13\\httpd.exe -d C:/cdb/CONTACT_Elements_Server_15.3.13 -d C:/cdb/CONTACT_Elements_Server_15.3.13 -f C:/cdb/rbei/tmp/httpaclxlf.conf -D WIN32 -D USE_SSL -D USE_CACHE'
[2019-01-25 16:02:23.399407] [mpm_winnt:notice] [pid 12640:tid 852] mpm_winnt.c(649): AH00418: Parent: Created child process 13052
[2019-01-25 16:02:30.554997] [mpm_winnt:notice] [pid 13052:tid 824] child.c(968): AH00354: Child: Starting 256 worker threads.
[2019-01-25 16:10:06.807425] [cache:error] [pid 13052:tid 3012] [client fe80::91bf:dbee:3230:e1f1:62877] [TJpQ803qZAU] [(OS 5)Access is denied.  ] cache_util.c(355): AH00779: Could not stat a cache lock file: C:/cdb/rbei/etcd/mod_cache-lock/s/j/sjyc@B3yr4kSljHqiiW0Dg
[2019-01-25 16:10:21.813899] [cache:error] [pid 13052:tid 3004] [client fe80::91bf:dbee:3230:e1f1:62884] [l7I19J1JZAU] [(OS 5)Access is denied.  ] cache_util.c(355): AH00779: Could not stat a cache lock file: C:/cdb/rbei/etcd/mod_cache-lock/s/j/sjyc@B3yr4kSljHqiiW0Dg
[2019-01-25 16:10:21.814370] [cache:error] [pid 13052:tid 3004] [client fe80::91bf:dbee:3230:e1f1:62884] [l7I19J1JZAU] [(OS 5)Access is denied.  ] cache_util.c(355): AH00779: Could not stat a cache lock file: C:/cdb/rbei/etcd/mod_cache-lock/s/j/sjyc@B3yr4kSljHqiiW0Dg
[2019-01-28 10:56:49.302451] [wsgi:error] [pid 13052:tid 2996] [client fe80::91bf:dbee:3230:e1f1:60733] [SMZT7PXqYwU] wsgi_logger.c(147): [ERROR] Could not connect to worker for user 'caddok' at port 59886!
[2019-01-28 10:56:51.568320] [wsgi:error] [pid 13052:tid 2992] [client fe80::91bf:dbee:3230:e1f1:60734] [fvdU7GXKZAU] wsgi_logger.c(628): mod_wsgi (pid=13052): Exception occurred processing WSGI script 'C:/cdb/CONTACT_Elements_Server_15.3.13/cdb/python/cdb/wsgi/dispatcher/app.py'.
[2019-01-28 10:56:51.568320] [wsgi:error] [pid 13052:tid 2992] [client fe80::91bf:dbee:3230:e1f1:60734] [fvdU7GXKZAU] wsgi_logger.c(147): Traceback (most recent call last):
[2019-01-28 10:56:51.568320] [wsgi:error] [pid 13052:tid 2992] [client fe80::91bf:dbee:3230:e1f1:60734] [fvdU7GXKZAU] wsgi_logger.c(147):   File "C:\\cdb\\CONTACT_Elements_Server_15.3.13\\cdb\\python\\cdb\\wsgi\\middleware.py", line 708, in __call__
[2019-01-28 10:56:51.599573] [wsgi:error] [pid 13052:tid 2992] [client fe80::91bf:dbee:3230:e1f1:60734] [fvdU7GXKZAU] wsgi_logger.c(147):     return self.app(environ, start_response)
[2019-01-28 10:56:51.599573] [wsgi:error] [pid 13052:tid 2992] [client fe80::91bf:dbee:3230:e1f1:60734] [fvdU7GXKZAU] wsgi_logger.c(147):   File "C:\\cdb\\CONTACT_Elements_Server_15.3.13\\cdb\\python\\cdb\\wsgi\\middleware.py", line 736, in __call__
[2019-01-28 10:56:51.599573] [wsgi:error] [pid 13052:tid 2992] [client fe80::91bf:dbee:3230:e1f1:60734] [fvdU7GXKZAU] wsgi_logger.c(147):     return self.app(environ, check_status)
[2019-01-28 10:56:51.599573] [wsgi:error] [pid 13052:tid 2992] [client fe80::91bf:dbee:3230:e1f1:60734] [fvdU7GXKZAU] wsgi_logger.c(147):   File "C:\\cdb\\CONTACT_Elements_Server_15.3.13\\cdb\\python\\cdb\\wsgi\\middleware.py", line 759, in __call__
[2019-01-28 10:56:51.599573] [wsgi:error] [pid 13052:tid 2992] [client fe80::91bf:dbee:3230:e1f1:60734] [fvdU7GXKZAU] wsgi_logger.c(147):     return self.app(environ, _remove_content_length)
[2019-01-28 10:56:51.599573] [wsgi:error] [pid 13052:tid 2992] [client fe80::91bf:dbee:3230:e1f1:60734] [fvdU7GXKZAU] wsgi_logger.c(147):   File "C:\\cdb\\CONTACT_Elements_Server_15.3.13\\cdb\\python\\cdb\\wsgi\\dispatcher\\helpers.py", line 132, in __call__
[2019-01-28 10:56:51.615200] [wsgi:error] [pid 13052:tid 2992] [client fe80::91bf:dbee:3230:e1f1:60734] [fvdU7GXKZAU] wsgi_logger.c(147):     return app(environ, start_response)
[2019-01-28 10:56:51.646453] [wsgi:error] [pid 13052:tid 2992] [client fe80::91bf:dbee:3230:e1f1:60734] [fvdU7GXKZAU] wsgi_logger.c(147):   File "C:\\cdb\\CONTACT_Elements_Server_15.3.13\\cdb\\python\\cdb\\wsgi\\middleware.py", line 126, in __call__
[2019-01-28 10:56:51.646453] [wsgi:error] [pid 13052:tid 2992] [client fe80::91bf:dbee:3230:e1f1:60734] [fvdU7GXKZAU] wsgi_logger.c(147):     environ, start_response)
[2019-01-28 10:56:51.646453] [wsgi:error] [pid 13052:tid 2992] [client fe80::91bf:dbee:3230:e1f1:60734] [fvdU7GXKZAU] wsgi_logger.c(147):   File "C:\\cdb\\CONTACT_Elements_Server_15.3.13\\lib\\site-packages\\beaker-1.9.0-py2.7.egg\\beaker\\middleware.py", line 156, in __call__
[2019-01-28 10:56:51.865227] [wsgi:error] [pid 13052:tid 2992] [client fe80::91bf:dbee:3230:e1f1:60734] [fvdU7GXKZAU] wsgi_logger.c(147):     return self.wrap_app(environ, session_start_response)
[2019-01-28 10:56:51.865227] [wsgi:error] [pid 13052:tid 2992] [client fe80::91bf:dbee:3230:e1f1:60734] [fvdU7GXKZAU] wsgi_logger.c(147):   File "C:\\cdb\\CONTACT_Elements_Server_15.3.13\\cdb\\python\\cdb\\wsgi\\dispatcher\\helpers.py", line 594, in __call__
[2019-01-28 10:56:51.865227] [wsgi:error] [pid 13052:tid 2992] [client fe80::91bf:dbee:3230:e1f1:60734] [fvdU7GXKZAU] wsgi_logger.c(147):     return self.app(environ, start_response)
[2019-01-28 10:56:51.865227] [wsgi:error] [pid 13052:tid 2992] [client fe80::91bf:dbee:3230:e1f1:60734] [fvdU7GXKZAU] wsgi_logger.c(147):   File "C:\\cdb\\CONTACT_Elements_Server_15.3.13\\cdb\\python\\cdb\\wsgi\\middleware.py", line 292, in __call__
[2019-01-28 10:56:51.865227] [wsgi:error] [pid 13052:tid 2992] [client fe80::91bf:dbee:3230:e1f1:60734] [fvdU7GXKZAU] wsgi_logger.c(147):     return self.app(environ, start_response)
[2019-01-28 10:56:51.865227] [wsgi:error] [pid 13052:tid 2992] [client fe80::91bf:dbee:3230:e1f1:60734] [fvdU7GXKZAU] wsgi_logger.c(147):   File "C:\\cdb\\CONTACT_Elements_Server_15.3.13\\cdb\\python\\cdb\\wsgi\\middleware.py", line 244, in __call__
[2019-01-28 10:56:51.865227] [wsgi:error] [pid 13052:tid 2992] [client fe80::91bf:dbee:3230:e1f1:60734] [fvdU7GXKZAU] wsgi_logger.c(147):     return self.app(environ, add_headers)
[2019-01-28 10:56:51.865227] [wsgi:error] [pid 13052:tid 2992] [client fe80::91bf:dbee:3230:e1f1:60734] [fvdU7GXKZAU] wsgi_logger.c(147):   File "C:\\cdb\\CONTACT_Elements_Server_15.3.13\\cdb\\python\\cdb\\wsgi\\middleware.py", line 268, in __call__
[2019-01-28 10:56:51.865227] [wsgi:error] [pid 13052:tid 2992] [client fe80::91bf:dbee:3230:e1f1:60734] [fvdU7GXKZAU] wsgi_logger.c(147):     return self.app(environ, add_header)
[2019-01-28 10:56:51.865227] [wsgi:error] [pid 13052:tid 2992] [client fe80::91bf:dbee:3230:e1f1:60734] [fvdU7GXKZAU] wsgi_logger.c(147):   File "C:\\cdb\\CONTACT_Elements_Server_15.3.13\\cdb\\python\\cdb\\wsgi\\dispatcher\\helpers.py", line 355, in __call__
[2019-01-28 10:56:51.865227] [wsgi:error] [pid 13052:tid 2992] [client fe80::91bf:dbee:3230:e1f1:60734] [fvdU7GXKZAU] wsgi_logger.c(147):     app, app_name, path_components)
[2019-01-28 10:56:51.865227] [wsgi:error] [pid 13052:tid 2992] [client fe80::91bf:dbee:3230:e1f1:60734] [fvdU7GXKZAU] wsgi_logger.c(147):   File "C:\\cdb\\CONTACT_Elements_Server_15.3.13\\cdb\\python\\cdb\\wsgi\\dispatcher\\helpers.py", line 198, in _handle_logged_in
[2019-01-28 10:56:51.865227] [wsgi:error] [pid 13052:tid 2992] [client fe80::91bf:dbee:3230:e1f1:60734] [fvdU7GXKZAU] wsgi_logger.c(147):     return app(environ, start_response)
[2019-01-28 10:56:51.865227] [wsgi:error] [pid 13052:tid 2992] [client fe80::91bf:dbee:3230:e1f1:60734] [fvdU7GXKZAU] wsgi_logger.c(147):   File "C:\\cdb\\CONTACT_Elements_Server_15.3.13\\cdb\\python\\cdb\\wsgi\\auth\\sso.py", line 124, in __call__
[2019-01-28 10:56:51.912106] [wsgi:error] [pid 13052:tid 2992] [client fe80::91bf:dbee:3230:e1f1:60734] [fvdU7GXKZAU] wsgi_logger.c(147):     return self.app(env, start_response)
[2019-01-28 10:56:51.912106] [wsgi:error] [pid 13052:tid 2992] [client fe80::91bf:dbee:3230:e1f1:60734] [fvdU7GXKZAU] wsgi_logger.c(147):   File "C:\\cdb\\CONTACT_Elements_Server_15.3.13\\cdb\\python\\cdb\\wsgi\\middleware.py", line 775, in __call__
[2019-01-28 10:56:51.912106] [wsgi:error] [pid 13052:tid 2992] [client fe80::91bf:dbee:3230:e1f1:60734] [fvdU7GXKZAU] wsgi_logger.c(147):     return self.app(env, start_response)
[2019-01-28 10:56:51.912106] [wsgi:error] [pid 13052:tid 2992] [client fe80::91bf:dbee:3230:e1f1:60734] [fvdU7GXKZAU] wsgi_logger.c(147):   File "C:\\cdb\\CONTACT_Elements_Server_15.3.13\\cdb\\python\\cdb\\wsgi\\dispatcher\\helpers.py", line 468, in __call__
[2019-01-28 10:56:51.912106] [wsgi:error] [pid 13052:tid 2992] [client fe80::91bf:dbee:3230:e1f1:60734] [fvdU7GXKZAU] wsgi_logger.c(147):     return self.app(environ, start_response)
[2019-01-28 10:56:51.912106] [wsgi:error] [pid 13052:tid 2992] [client fe80::91bf:dbee:3230:e1f1:60734] [fvdU7GXKZAU] wsgi_logger.c(147):   File "C:\\cdb\\CONTACT_Elements_Server_15.3.13\\cdb\\python\\cdb\\wsgi\\dispatcher\\helpers.py", line 552, in __call__
[2019-01-28 10:56:51.912106] [wsgi:error] [pid 13052:tid 2992] [client fe80::91bf:dbee:3230:e1f1:60734] [fvdU7GXKZAU] wsgi_logger.c(147):     return self.app(env, start_response)
[2019-01-28 10:56:51.912106] [wsgi:error] [pid 13052:tid 2992] [client fe80::91bf:dbee:3230:e1f1:60734] [fvdU7GXKZAU] wsgi_logger.c(147):   File "C:\\cdb\\CONTACT_Elements_Server_15.3.13\\cdb\\python\\cdb\\wsgi\\middleware.py", line 505, in __call__
[2019-01-28 10:56:51.912106] [wsgi:error] [pid 13052:tid 2992] [client fe80::91bf:dbee:3230:e1f1:60734] [fvdU7GXKZAU] wsgi_logger.c(147):     return self.app(environ, modified_start_response)
[2019-01-28 10:56:51.912106] [wsgi:error] [pid 13052:tid 2992] [client fe80::91bf:dbee:3230:e1f1:60734] [fvdU7GXKZAU] wsgi_logger.c(147):   File "C:\\cdb\\CONTACT_Elements_Server_15.3.13\\cdb\\python\\cdb\\wsgi\\middleware.py", line 414, in __call__
[2019-01-28 10:56:51.912106] [wsgi:error] [pid 13052:tid 2992] [client fe80::91bf:dbee:3230:e1f1:60734] [fvdU7GXKZAU] wsgi_logger.c(147):     return self.app(environ, start_response)
[2019-01-28 10:56:51.912106] [wsgi:error] [pid 13052:tid 2992] [client fe80::91bf:dbee:3230:e1f1:60734] [fvdU7GXKZAU] wsgi_logger.c(147):   File "C:\\cdb\\CONTACT_Elements_Server_15.3.13\\cdb\\python\\cdb\\wsgi\\middleware.py", line 899, in __call__
[2019-01-28 10:56:51.912106] [wsgi:error] [pid 13052:tid 2992] [client fe80::91bf:dbee:3230:e1f1:60734] [fvdU7GXKZAU] wsgi_logger.c(147):     return self.app(env, start_response)
[2019-01-28 10:56:51.912106] [wsgi:error] [pid 13052:tid 2992] [client fe80::91bf:dbee:3230:e1f1:60734] [fvdU7GXKZAU] wsgi_logger.c(147):   File "C:\\cdb\\CONTACT_Elements_Server_15.3.13\\cdb\\python\\cdb\\wsgi\\middleware.py", line 456, in __call__
[2019-01-28 10:56:51.912106] [wsgi:error] [pid 13052:tid 2992] [client fe80::91bf:dbee:3230:e1f1:60734] [fvdU7GXKZAU] wsgi_logger.c(147):     return self._get_proxy(host, port)(local_environ, start_response)
[2019-01-28 10:56:51.912106] [wsgi:error] [pid 13052:tid 2992] [client fe80::91bf:dbee:3230:e1f1:60734] [fvdU7GXKZAU] wsgi_logger.c(147):   File "C:\\cdb\\CONTACT_Elements_Server_15.3.13\\cdb\\python\\cdb\\wsgi\\proxy.py", line 358, in __call__
[2019-01-28 10:56:51.943360] [wsgi:error] [pid 13052:tid 2992] [client fe80::91bf:dbee:3230:e1f1:60734] [fvdU7GXKZAU] wsgi_logger.c(147):     self.handle_call(my_environ, uri, streamer)
[2019-01-28 10:56:51.943360] [wsgi:error] [pid 13052:tid 2992] [client fe80::91bf:dbee:3230:e1f1:60734] [fvdU7GXKZAU] wsgi_logger.c(147):   File "C:\\cdb\\CONTACT_Elements_Server_15.3.13\\cdb\\python\\cdb\\wsgi\\proxy.py", line 276, in handle_call
[2019-01-28 10:56:51.943360] [wsgi:error] [pid 13052:tid 2992] [client fe80::91bf:dbee:3230:e1f1:60734] [fvdU7GXKZAU] wsgi_logger.c(147):     if "perform() is currently running" in e.args[0]:
[2019-01-28 10:56:51.943360] [wsgi:error] [pid 13052:tid 2992] [client fe80::91bf:dbee:3230:e1f1:60734] [fvdU7GXKZAU] wsgi_logger.c(147): TypeError: argument of type 'int' is not iterable
[2019-01-28 10:56:54.209228] [wsgi:error] [pid 13052:tid 2992] [client fe80::91bf:dbee:3230:e1f1:60745] [w1e27IX/NBo] wsgi_logger.c(147): [ERROR] Failed to get worker_host/port from session. PATH: /server/__keep_alive__ LOGIN: caddok
[2019-01-28 10:56:54.209228] [wsgi:error] [pid 13052:tid 2992] [client fe80::91bf:dbee:3230:e1f1:60745] [w1e27IX/NBo] wsgi_logger.c(147): [ERROR] Could not connect to worker for user 'caddok' at port unknown!
[2019-01-28 10:58:13.792202] [wsgi:error] [pid 13052:tid 2992] [client fe80::91bf:dbee:3230:e1f1:61022] [wa508cV/NBo] wsgi_logger.c(147): [ERROR] Failed to get worker_host/port from session. PATH: /server/__keep_alive__ LOGIN: caddok
[2019-01-28 10:58:13.792202] [wsgi:error] [pid 13052:tid 2992] [client fe80::91bf:dbee:3230:e1f1:61022] [wa508cV/NBo] wsgi_logger.c(147): [ERROR] Could not connect to worker for user 'caddok' at port unknown!
[2019-01-28 11:08:13.830014] [wsgi:error] [pid 13052:tid 2992] [client fe80::91bf:dbee:3230:e1f1:57082] [fsU4FcZ/NBo] wsgi_logger.c(147): [ERROR] Failed to get worker_host/port from session. PATH: /server/__keep_alive__ LOGIN: caddok
[2019-01-28 11:08:13.830014] [wsgi:error] [pid 13052:tid 2992] [client fe80::91bf:dbee:3230:e1f1:57082] [fsU4FcZ/NBo] wsgi_logger.c(147): [ERROR] Could not connect to worker for user 'caddok' at port unknown!
[2019-01-28 11:11:46.988770] [wsgi:error] [pid 13052:tid 2992] [client fe80::91bf:dbee:3230:e1f1:57164] [4lDtIaY/NBo] wsgi_logger.c(147): [ERROR] Failed to get worker_host/port from session. PATH: /internal/activitystream/posting LOGIN: caddok
[2019-01-28 11:11:46.988770] [wsgi:error] [pid 13052:tid 2992] [client fe80::91bf:dbee:3230:e1f1:57164] [4lDtIaY/NBo] wsgi_logger.c(147): [ERROR] Could not connect to worker for user 'caddok' at port unknown!
[2019-01-28 11:18:13.850208] [wsgi:error] [pid 13052:tid 2992] [client fe80::91bf:dbee:3230:e1f1:57296] [YFr8OCa5Wxg] wsgi_logger.c(147): [ERROR] Failed to get worker_host/port from session. PATH: /server/__keep_alive__ LOGIN: caddok
[2019-01-28 11:18:13.850208] [wsgi:error] [pid 13052:tid 2992] [client fe80::91bf:dbee:3230:e1f1:57296] [YFr8OCa5Wxg] wsgi_logger.c(147): [ERROR] Could not connect to worker for user 'caddok' at port unknown!
[2019-01-28 11:26:47.014857] [wsgi:error] [pid 13052:tid 2992] [client fe80::91bf:dbee:3230:e1f1:57439] [yWWSV3bqZAU] wsgi_logger.c(147): [ERROR] Failed to get worker_host/port from session. PATH: /internal/activitystream/posting LOGIN: caddok
[2019-01-28 11:26:47.014857] [wsgi:error] [pid 13052:tid 2992] [client fe80::91bf:dbee:3230:e1f1:57439] [yWWSV3bqZAU] wsgi_logger.c(147): [ERROR] Could not connect to worker for user 'caddok' at port unknown!
[2019-01-28 11:28:13.867488] [wsgi:error] [pid 13052:tid 2992] [client fe80::91bf:dbee:3230:e1f1:57464] [4OO/XDaRARo] wsgi_logger.c(147): [ERROR] Failed to get worker_host/port from session. PATH: /server/__keep_alive__ LOGIN: caddok
[2019-01-28 11:28:13.867488] [wsgi:error] [pid 13052:tid 2992] [client fe80::91bf:dbee:3230:e1f1:57464] [4OO/XDaRARo] wsgi_logger.c(147): [ERROR] Could not connect to worker for user 'caddok' at port unknown!
[2019-01-28 11:38:13.882434] [wsgi:error] [pid 13052:tid 2992] [client fe80::91bf:dbee:3230:e1f1:57683] [QmSDgDaRARo] wsgi_logger.c(147): [ERROR] Failed to get worker_host/port from session. PATH: /server/__keep_alive__ LOGIN: caddok
[2019-01-28 11:38:13.882434] [wsgi:error] [pid 13052:tid 2992] [client fe80::91bf:dbee:3230:e1f1:57683] [QmSDgDaRARo] wsgi_logger.c(147): [ERROR] Could not connect to worker for user 'caddok' at port unknown!
[2019-01-28 11:41:47.085122] [wsgi:error] [pid 13052:tid 2992] [client fe80::91bf:dbee:3230:e1f1:57743] [d5M4jSa5Wxg] wsgi_logger.c(147): [ERROR] Failed to get worker_host/port from session. PATH: /internal/activitystream/posting LOGIN: caddok
[2019-01-28 11:41:47.085122] [wsgi:error] [pid 13052:tid 2992] [client fe80::91bf:dbee:3230:e1f1:57743] [d5M4jSa5Wxg] wsgi_logger.c(147): [ERROR] Could not connect to worker for user 'caddok' at port unknown!
[2019-01-28 11:45:17.920830] [wsgi:error] [pid 13052:tid 2996] [client fe80::91bf:dbee:3230:e1f1:57813] [KDrJmSa5Wxg] wsgi_logger.c(628): mod_wsgi (pid=13052): Exception occurred processing WSGI script 'C:/cdb/CONTACT_Elements_Server_15.3.13/cdb/python/cdb/wsgi/dispatcher/app.py'.
[2019-01-28 11:45:17.920830] [wsgi:error] [pid 13052:tid 2996] [client fe80::91bf:dbee:3230:e1f1:57813] [KDrJmSa5Wxg] wsgi_logger.c(147): IOError: [Errno 9] Bad file descriptor
[2019-01-28 11:45:23.265154] [wsgi:error] [pid 13052:tid 2992] [client fe80::91bf:dbee:3230:e1f1:57811] [YokammbJZgU] wsgi_logger.c(628): mod_wsgi (pid=13052): Exception occurred processing WSGI script 'C:/cdb/CONTACT_Elements_Server_15.3.13/cdb/python/cdb/wsgi/dispatcher/app.py'.
[2019-01-28 11:45:23.265154] [wsgi:error] [pid 13052:tid 2992] [client fe80::91bf:dbee:3230:e1f1:57811] [YokammbJZgU] wsgi_logger.c(147): IOError: [Errno 9] Bad file descriptor
[2019-01-28 11:48:13.924890] [wsgi:error] [pid 13052:tid 2996] [client fe80::91bf:dbee:3230:e1f1:57862] [qzFHpPbqYwU] wsgi_logger.c(147): [ERROR] Failed to get worker_host/port from session. PATH: /server/__keep_alive__ LOGIN: caddok
[2019-01-28 11:48:13.925892] [wsgi:error] [pid 13052:tid 2996] [client fe80::91bf:dbee:3230:e1f1:57862] [qzFHpPbqYwU] wsgi_logger.c(147): [ERROR] Could not connect to worker for user 'caddok' at port unknown!
[2019-01-28 11:52:11.927401] [wsgi:error] [pid 13052:tid 2996] [client fe80::91bf:dbee:3230:e1f1:57932] [afF2ssZ/NBo] wsgi_logger.c(147): [ERROR] Failed to get worker_host/port from session. PATH: /server/invoke LOGIN: caddok
[2019-01-28 11:52:11.927401] [wsgi:error] [pid 13052:tid 2996] [client fe80::91bf:dbee:3230:e1f1:57932] [afF2ssZ/NBo] wsgi_logger.c(147): [ERROR] Could not connect to worker for user 'caddok' at port unknown!
[2019-01-28 11:52:12.521212] [wsgi:error] [pid 13052:tid 2992] [client fe80::91bf:dbee:3230:e1f1:57933] [/ACAsob/NBo] wsgi_logger.c(147): [ERROR] Failed to get worker_host/port from session. PATH: /server/invoke LOGIN: caddok
[2019-01-28 11:52:12.521212] [wsgi:error] [pid 13052:tid 2992] [client fe80::91bf:dbee:3230:e1f1:57933] [/ACAsob/NBo] wsgi_logger.c(147): [ERROR] Could not connect to worker for user 'caddok' at port unknown!
[2019-01-28 11:52:12.521212] [wsgi:error] [pid 13052:tid 2988] [client fe80::91bf:dbee:3230:e1f1:57934] [/ACAstapZQU] wsgi_logger.c(147): [ERROR] Failed to get worker_host/port from session. PATH: /server/invoke LOGIN: caddok
[2019-01-28 11:52:12.521212] [wsgi:error] [pid 13052:tid 2988] [client fe80::91bf:dbee:3230:e1f1:57934] [/ACAstapZQU] wsgi_logger.c(147): [ERROR] Could not connect to worker for user 'caddok' at port unknown!
[2019-01-28 11:52:12.536840] [wsgi:error] [pid 13052:tid 3012] [client fe80::91bf:dbee:3230:e1f1:57935] [/ACAsia5Wxg] wsgi_logger.c(147): [ERROR] Failed to get worker_host/port from session. PATH: /server/invoke LOGIN: caddok
[2019-01-28 11:52:12.536840] [wsgi:error] [pid 13052:tid 3012] [client fe80::91bf:dbee:3230:e1f1:57935] [/ACAsia5Wxg] wsgi_logger.c(147): [ERROR] Could not connect to worker for user 'caddok' at port unknown!
[2019-01-28 11:52:12.552468] [wsgi:error] [pid 13052:tid 2980] [client fe80::91bf:dbee:3230:e1f1:57936] [FHuAsmbJZgU] wsgi_logger.c(147): [ERROR] Failed to get worker_host/port from session. PATH: /server/__quit__ LOGIN: caddok
